Workbook

Sheet Executive_Summary
A1: MLI / MWA HORIZONTAL CONSOLIDATION — EXECUTIVE SUMMARY
A2: Hypothetical, independently-built analysis using public FY2025 filings. Not an announced or advised transaction.
A4: Acquirer | B4: Mueller Industries, Inc. (NYSE: MLI)
A5: Target | B5: Mueller Water Products, Inc. (NYSE: MWA)
A6: MLI FY2025 Net Sales ($M) | B6: =MLI_Standalone!B4 -> 4178.5
A7: MWA FY2025 Net Sales ($M) | B7: =MWA_Standalone!B4 -> 1429.7
A8: Pro Forma Net Sales ($M) | B8: =Pro_Forma_Consolidated!E5 -> 5608.2
A9: Pro Forma EBITDA ($M) | B9: =Pro_Forma_Consolidated!E9 -> 1339.3
A10: Pro Forma EBITDA Margin % | B10: =Pro_Forma_Consolidated!E10 -> 0.23881103

Sheet MLI_Standalone
A1: MUELLER INDUSTRIES (NYSE: MLI) — STANDALONE, FY2025
A2: Source: MLI FY2025 10-K, Results of Operations (filed Feb 2026), SEC EDGAR. All figures $ millions.
A4: Net Sales | B4: 4178.5
A5: Cost of Goods Sold | B5: 2966.1
A6: Depreciation & Amortization | B6: 68.6
A7: SG&A Expense | B7: 248.7
A9: Gross Profit | B9: =B4-B5 -> 1212.4
A10: Gross Margin % | B10: =B9/B4 -> 0.29015197
A12: Operating Income (company-reported) | B12: 958.5
A13: EBITDA (company-reported) | B13: 1027.1
A14: EBITDA Margin % | B14: =B13/B4 -> 0.24580591
A16: Net Income (reported, incl. non-operating items & tax) | B16: 765.2
A17: Reconciling gap check
A18: Component build (Gross Profit - D&A - SG&A) | B18: =B9-B6-B7 -> 895.1
A19: Gap vs. reported Operating Income | B19: =B18-B12 -> -63.4 | C19: ~$(63)M gap: the three disclosed line items (COGS/D&A/SG&A) do not fully reconcile to reported Operating Income — likely unallocated corporate costs not broken out in the excerpt pulled. Confirm against the full 10-K segment footnote before relying on the component split; the headline Operating Income/EBITDA above are the authoritative, reported figures.
A21: Total Debt (FY2025, per 10-K) | B21: 0
A22: Cash & Short-Term Investments (FY2025) | B22: 1389.7
A23: Capital Expenditures (FY2025 actual) | B23: 68.8
A24: FY2026 CapEx Guidance — Low / High ($M) | B24: 80 | C24: 90
A25: Dividend Payout Ratio (trailing) | B25: 0.1512

Sheet MWA_Standalone
A1: MUELLER WATER PRODUCTS (NYSE: MWA) — STANDALONE, FY2025
A2: Source: MWA FY2025 10-K (filed 2025-11-19) and Q4/FY2025 earnings release. All figures $ millions.
A4: Net Sales | B4: 1429.7
A5: Cost of Goods Sold | B5: 913
A7: Gross Profit | B7: =B4-B5 -> 516.7
A8: Gross Margin % | B8: =B7/B4 -> 0.36140449
A10: Operating Expenses Below Gross Profit (SG&A + other) | B10: 256.1
A11: Operating Income | B11: =B7-B10 -> 260.6 | C11: Should tie to reported Operating Income of $260.6M
A13: Adjusted EBITDA (company-reported, non-GAAP) | B13: 326.2
A14: Adjusted EBITDA Margin % | B14: =B13/B4 -> 0.22815975
A16: Net Income (reported) | B16: 191.7
A18: Total Debt (FY2025, per 10-K/earnings release) | B18: 451.6
A19: Cash & Cash Equivalents (FY2025) | B19: 431.5
A20: Capital Expenditures (FY2025 actual) | B20: 47.3
A21: Dividend Payout Ratio (trailing) | B21: 0.2
A22: Implied D&A (unadjusted EBITDA less Operating Income) | B22: 46.9

Sheet Copper_Cost_Engine
A1: COPPER COST ENGINE & PASS-THROUGH DYNAMICS (FIXED)
A2: Current/prior COMEX averages are real company-disclosed figures (MLI earnings releases). Fabrication spread and pass-through alpha are illustrative analyst assumptions pending validation — flagged, not sourced.
A4: Current-Quarter COMEX Copper Avg ($/lb) | B4: 5.13
A5: Prior-Quarter COMEX Copper Avg ($/lb) | B5: 4.83
A6: Pass-Through Pricing Lag (Days) | B6: 45
A7: Base Fabrication Spread ($/lb) | B7: 0.3
A8: Pass-Through Efficiency (Alpha) | B8: 0.85
A11: Effective Procurement Cost ($/lb) | B11: =B5+(B4-B5)*(1-B6/365) -> 5.0930137 | C11: Formula: PriorPrice + (CurrentPrice-PriorPrice) x (1 - Lag/365). At Lag=0 this equals CurrentPrice; at Lag=365 it equals PriorPrice.
A12: Realized Selling Price (ASP, $/lb) | B12: =B7+B8*B4+(1-B8)*B5 -> 5.385 | C12: Formula: FabricationSpread + Alpha x CurrentPrice + (1-Alpha) x PriorPrice
A13: Realized Unit Margin Spread ($/lb) | B13: =B12-B11 -> 0.2919863
A15: Formula check: at Lag=0, Effective Cost should equal Current Price | B15: =IF(ROUND(B5+(B4-B5)*(1-0/365),4)=ROUND(B4,4),"PASS","FAIL") -> PASS

Sheet Pro_Forma_Consolidated
A1: MLI / MWA — PRO FORMA CONSOLIDATED (HYPOTHETICAL)
A2: Illustrative combination for CV/portfolio purposes — not an announced transaction. Synergy figures are analyst assumptions, not disclosed guidance.
A4: Metric | B4: MLI Standalone | C4: MWA Standalone | D4: Synergies / Adj. | E4: Pro Forma Combined
A5: Net Sales | B5: =MLI_Standalone!B4 -> 4178.5 | C5: =MWA_Standalone!B4 -> 1429.7 | D5: 0 | E5: =B5+C5+D5 -> 5608.2
A6: COGS (informational — copper-sensitivity link only) | B6: =MLI_Standalone!B5 -> 2966.1 | C6: =MWA_Standalone!B5 -> 913 | D6: -8 | E6: =B6+C6+D6 -> 3871.1
A7: Gross Profit (informational) | B7: =B5-B6 -> 1212.4 | C7: =C5-C6 -> 516.7 | D7: =D5-D6 -> 8 | E7: =E5-E6 -> 1737.1
A9: EBITDA (built from reported headline figures, not re-derived) | B9: =MLI_Standalone!B13 -> 1027.1 | C9: =MWA_Standalone!B13 -> 326.2 | D9: -14 | E9: =B9+C9+D9 -> 1339.3
A10: EBITDA Margin % | B10: =B9/B5 -> 0.24580591 | C10: =C9/C5 -> 0.22815975 | E10: =E9/E5 -> 0.23881103
A12: Pro forma EBITDA (E9) must equal MLI EBITDA + MWA EBITDA + net synergies — checked on Audit_Checks tab.

Sheet Sensitivity_Matrix
A1: 2D SENSITIVITY — PRO FORMA EBITDA
A2: Rows: copper price shock applied to Current-Quarter COMEX price. Columns: % of assumed synergies realized. Values: Pro Forma EBITDA ($M).
A4: Copper Price Shock \ Synergy Realization | B4: 0.5 | C4: 0.75 | D4: 1 | E4: 1.25
A5: -0.2 | B5: =Five_Year_Forecast!C39-MLI_Standalone!B5*-0.2*0.6+Five_Year_Forecast!C40+(-8+-6)*0.5 -> 1759.9064 | C5: =Five_Year_Forecast!C39-MLI_Standalone!B5*-0.2*0.6+Five_Year_Forecast!C40+(-8+-6)*0.75 -> 1756.4064 | D5: =Five_Year_Forecast!C39-MLI_Standalone!B5*-0.2*0.6+Five_Year_Forecast!C40+(-8+-6)*1 -> 1752.9064 | E5: =Five_Year_Forecast!C39-MLI_Standalone!B5*-0.2*0.6+Five_Year_Forecast!C40+(-8+-6)*1.25 -> 1749.4064
A6: -0.1 | B6: =Five_Year_Forecast!C39-MLI_Standalone!B5*-0.1*0.6+Five_Year_Forecast!C40+(-8+-6)*0.5 -> 1581.9404 | C6: =Five_Year_Forecast!C39-MLI_Standalone!B5*-0.1*0.6+Five_Year_Forecast!C40+(-8+-6)*0.75 -> 1578.4404 | D6: =Five_Year_Forecast!C39-MLI_Standalone!B5*-0.1*0.6+Five_Year_Forecast!C40+(-8+-6)*1 -> 1574.9404 | E6: =Five_Year_Forecast!C39-MLI_Standalone!B5*-0.1*0.6+Five_Year_Forecast!C40+(-8+-6)*1.25 -> 1571.4404
A7: 0 | B7: =Five_Year_Forecast!C39-MLI_Standalone!B5*0*0.6+Five_Year_Forecast!C40+(-8+-6)*0.5 -> 1403.9744 | C7: =Five_Year_Forecast!C39-MLI_Standalone!B5*0*0.6+Five_Year_Forecast!C40+(-8+-6)*0.75 -> 1400.4744 | D7: =Five_Year_Forecast!C39-MLI_Standalone!B5*0*0.6+Five_Year_Forecast!C40+(-8+-6)*1 -> 1396.9744 | E7: =Five_Year_Forecast!C39-MLI_Standalone!B5*0*0.6+Five_Year_Forecast!C40+(-8+-6)*1.25 -> 1393.4744
A8: 0.1 | B8: =Five_Year_Forecast!C39-MLI_Standalone!B5*0.1*0.6+Five_Year_Forecast!C40+(-8+-6)*0.5 -> 1226.0084 | C8: =Five_Year_Forecast!C39-MLI_Standalone!B5*0.1*0.6+Five_Year_Forecast!C40+(-8+-6)*0.75 -> 1222.5084 | D8: =Five_Year_Forecast!C39-MLI_Standalone!B5*0.1*0.6+Five_Year_Forecast!C40+(-8+-6)*1 -> 1219.0084 | E8: =Five_Year_Forecast!C39-MLI_Standalone!B5*0.1*0.6+Five_Year_Forecast!C40+(-8+-6)*1.25 -> 1215.5084
A9: 0.2 | B9: =Five_Year_Forecast!C39-MLI_Standalone!B5*0.2*0.6+Five_Year_Forecast!C40+(-8+-6)*0.5 -> 1048.0424 | C9: =Five_Year_Forecast!C39-MLI_Standalone!B5*0.2*0.6+Five_Year_Forecast!C40+(-8+-6)*0.75 -> 1044.5424 | D9: =Five_Year_Forecast!C39-MLI_Standalone!B5*0.2*0.6+Five_Year_Forecast!C40+(-8+-6)*1 -> 1041.0424 | E9: =Five_Year_Forecast!C39-MLI_Standalone!B5*0.2*0.6+Five_Year_Forecast!C40+(-8+-6)*1.25 -> 1037.5424
A11: Copper COGS sensitivity factor (0.6) and synergy base ($8M COGS + $6M opex) are illustrative assumptions — label them as such in any pitch, not as disclosed figures.

Sheet Five_Year_Forecast
A1: 5-YEAR FORECAST — PRO FORMA (ILLUSTRATIVE), REBUILT
A2: FY2025 column is actual, sourced data. FY2026E-FY2030E are projections. Every assumption below is labeled as illustrative/derived or as sourced guidance — see comments.
A3: Note: the FY2025A column here is the PRE-DEAL standalone baseline (zero synergies) used to anchor the forecast — it is not the same figure as Pro_Forma_Consolidated's FY2025 pro forma (which nets illustrative Day-1 synergies). The two tabs answer different questions: Pro_Forma_Consolidated asks 'what would combined FY2025 have looked like,' this tab asks 'where does the combined entity go from here.'
A4: REVENUE DRIVERS (volume x price/mix, not a flat blended rate)
A5: MLI volume growth %/yr | B5: 0.02
A6: MLI price/mix growth %/yr | B6: 0.02
A7: MWA volume growth %/yr | B7: 0.025
A8: MWA price growth %/yr | B8: 0.024
A9: MLI combined growth %/yr (derived) | B9: =(1+B5)*(1+B6)-1 -> 0.0404
A10: MWA combined growth %/yr (derived) | B10: =(1+B7)*(1+B8)-1 -> 0.0496
A12: MARGIN, COPPER & D&A ASSUMPTIONS
A13: Base-case copper price path | B13: Flat at Current-Qtr COMEX ($5.13/lb)
A14: MLI EBITDA margin (held flat) | B14: =MLI_Standalone!B14 -> 0.24580591
A15: MWA EBITDA margin (held flat) | B15: =MWA_Standalone!B14 -> 0.22815975
A16: MLI D&A as % of revenue | B16: =MLI_Standalone!B6/MLI_Standalone!B4 -> 0.016417375
A17: MWA D&A as % of revenue | B17: =MWA_Standalone!B22/MWA_Standalone!B4 -> 0.032804085
A19: CAPEX, SYNERGY, CREDIT & CASH-RETURN ASSUMPTIONS
A20: MLI FY2026E CapEx (disclosed guidance midpoint) | B20: =(MLI_Standalone!B24+MLI_Standalone!C24)/2 -> 85
A21: MLI CapEx %/revenue, FY2027E onward (implied by guidance) | B21: =B20/(MLI_Standalone!B4*(1+B9)) -> 0.019552315
A22: MWA CapEx as % of revenue | B22: =MWA_Standalone!B20/MWA_Standalone!B4 -> 0.033083864
A23: Total run-rate synergies ($M) | B23: 14
A24: Cost-to-achieve, total (x run-rate synergies) | B24: 1.2
A25: Blended effective tax rate | B25: 0.24
A26: MWA Senior Notes interest rate | B26: 0.04
A27: Incremental ΔNWC as % of revenue growth | B27: 0.08
A29: Synergy realization ramp (FY2026E col C onward) | C29: 0.25 | D29: 0.5 | E29: 0.75 | F29: 1 | G29: 1
A30: Cost-to-achieve cash outlay split (FY2026E col C onward) | C30: 0.6 | D30: 0.4 | E30: 0 | F30: 0 | G30: 0
A31: Cost-to-achieve is modeled as a one-time CASH outlay in the FCF bridge below, not an EBITDA reduction — consistent with how sponsors typically present 'adjusted' EBITDA while still cash-funding the integration.
A34: Metric | B34: FY2025A | C34: FY2026E | D34: FY2027E | E34: FY2028E | F34: FY2029E | G34: FY2030E
A35: MLI Net Sales | B35: =MLI_Standalone!B4 -> 4178.5 | C35: =B35*(1+$B$9) -> 4347.3114 | D35: =C35*(1+$B$9) -> 4522.9428 | E35: =D35*(1+$B$9) -> 4705.6697 | F35: =E35*(1+$B$9) -> 4895.7787 | G35: =F35*(1+$B$9) -> 5093.5682
A36: MWA Net Sales | B36: =MWA_Standalone!B4 -> 1429.7 | C36: =B36*(1+$B$10) -> 1500.6131 | D36: =C36*(1+$B$10) -> 1575.0435 | E36: =D36*(1+$B$10) -> 1653.1657 | F36: =E36*(1+$B$10) -> 1735.1627 | G36: =F36*(1+$B$10) -> 1821.2268
A37: Combined Net Sales | B37: =B35+B36 -> 5608.2 | C37: =C35+C36 -> 5847.9245 | D37: =D35+D36 -> 6097.9863 | E37: =E35+E36 -> 6358.8354 | F37: =F35+F36 -> 6630.9414 | G37: =G35+G36 -> 6914.795
A39: MLI EBITDA (margin held flat, copper-consistent) | B39: =B35*$B$14 -> 1027.1 | C39: =C35*$B$14 -> 1068.5948 | D39: =D35*$B$14 -> 1111.7661 | E39: =E35*$B$14 -> 1156.6814 | F39: =F35*$B$14 -> 1203.4114 | G39: =G35*$B$14 -> 1252.0292
A40: MWA EBITDA (margin held flat) | B40: =B36*$B$15 -> 326.2 | C40: =C36*$B$15 -> 342.37952 | D40: =D36*$B$15 -> 359.36154 | E40: =E36*$B$15 -> 377.18588 | F40: =F36*$B$15 -> 395.8943 | G40: =G36*$B$15 -> 415.53065
A41: Synergies realized | B41: 0 | C41: =$B$23*C29 -> 3.5 | D41: =$B$23*D29 -> 7 | E41: =$B$23*E29 -> 10.5 | F41: =$B$23*F29 -> 14 | G41: =$B$23*G29 -> 14
A42: Pro Forma EBITDA | B42: =B39+B40+B41 -> 1353.3 | C42: =C39+C40+C41 -> 1414.4744 | D42: =D39+D40+D41 -> 1478.1276 | E42: =E39+E40+E41 -> 1544.3673 | F42: =F39+F40+F41 -> 1613.3056 | G42: =G39+G40+G41 -> 1681.5598
A43: Pro Forma EBITDA Margin % | B43: =B42/B37 -> 0.24130737 | C43: =C42/C37 -> 0.2418763 | D43: =D42/D37 -> 0.24239602 | E43: =E42/E37 -> 0.24286952 | F43: =F42/F37 -> 0.24329964 | G43: =G42/G37 -> 0.24318289
A45: Less: D&A (MLI + MWA) | B45: =-(B35*$B$16+B36*$B$17) -> -115.5 | C45: =-(C35*$B$16+C36*$B$17) -> -120.59768 | D45: =-(D35*$B$16+D36*$B$17) -> -125.92271 | E45: =-(E35*$B$16+E36*$B$17) -> -131.48533 | F45: =-(F35*$B$16+F36*$B$17) -> -137.29626 | G45: =-(G35*$B$16+G36*$B$17) -> -143.36669
A46: EBIT | B46: =B42+B45 -> 1237.8 | C46: =C42+C45 -> 1293.8767 | D46: =D42+D45 -> 1352.2049 | E46: =E42+E45 -> 1412.882 | F46: =F42+F45 -> 1476.0094 | G46: =G42+G45 -> 1538.1931
A47: Less: Interest Expense (MWA Senior Notes only; MLI debt-free) | B47: =-MWA_Standalone!B18*$B$26 -> -18.064 | C47: =-MWA_Standalone!B18*$B$26 -> -18.064 | D47: =-MWA_Standalone!B18*$B$26 -> -18.064 | E47: =-MWA_Standalone!B18*$B$26 -> -18.064 | F47: =-MWA_Standalone!B18*$B$26 -> -18.064 | G47: =-MWA_Standalone!B18*$B$26 -> -18.064
...

Sheet Audit_Checks
A1: AUDIT CHECKS
A3: Pro forma Net Sales = MLI + MWA Net Sales | B3: =IF(ROUND(Pro_Forma_Consolidated!E5,1)=ROUND(MLI_Standalone!B4+MWA_Standalone!B4,1),"PASS","FAIL") -> PASS
A4: Pro forma EBITDA = MLI EBITDA + MWA Adj. EBITDA + net synergies | B4: =IF(ROUND(Pro_Forma_Consolidated!E9,1)=ROUND(MLI_Standalone!B13+MWA_Standalone!B13+-8+-6,1),"PASS","FAIL") -> PASS
A5: MWA standalone Operating Income ties to reported figure ($260.6M) | B5: =IF(ROUND(MWA_Standalone!B11,1)=260.6,"PASS","FAIL") -> PASS
A6: Copper engine: Effective Cost = Current Price when Lag = 0 | B6: =Copper_Cost_Engine!B15 -> PASS
A7: KNOWN GAP: MLI component build (GP-D&A-SG&A) vs. reported Op. Income | B7: =MLI_Standalone!B19 -> -63.4
A8: Forecast: FY2026E MLI CapEx uses disclosed guidance midpoint ($85.0M) | B8: =IF(ROUND(Five_Year_Forecast!C53,1)=ROUND(Five_Year_Forecast!B20,1),"PASS","FAIL") -> PASS
A9: Forecast: synergy ramp never exceeds 100% of run-rate | B9: =IF(MAX(Five_Year_Forecast!C29:G29)<=1,"PASS","FAIL") -> PASS
A10: Forecast: FY2026E cash = FY2025A cash + FY2026E Free Cash Flow (roll-forward ties) | B10: =IF(ROUND(Five_Year_Forecast!C63,1)=ROUND(Five_Year_Forecast!B63+Five_Year_Forecast!C59,1),"PASS","FAIL") -> PASS
A11: Forecast: synergies reach full $14.0M run-rate by FY2029E | B11: =IF(ROUND(Five_Year_Forecast!F41,1)=ROUND(Five_Year_Forecast!B23,1),"PASS","FAIL") -> PASS
